Workbook

Sheet Project_Info
A1: Project Name: | B1: Zaker AI Platform
A2: Client: | B2: zakerai.org
A3: Created By: | B3: QA Team (Atef, Mahmoud, Abdalhamid, Hamza, Kamel)
A4: Creation Date: | B4: 2026-07-13
A5: Reviewed by:
A6: Type of Testing: | B6: System / Functional / Regression
A7: Version: | B7: v1.0
A8: Total Requirements: | B8: 144
A9: Drive materials and show case | B9: https://drive.google.com/drive/folders/1a5FFjiuuONhmn_3RtTCtsmp3mwZWFaV2

Sheet Summary_Report
A1: Zaker AI - Test Execution Summary
A3: Metric | B3: Value | D3: Author | E3: Total | F3: Passed | G3: Failed | H3: Blocked | I3: Not Executed
A4: Total Requirements | B4: =COUNTA(Requirements!A2:A145) -> 144 | D4: M_Atef | E4: =COUNTIF(Test_Cases!M2:M368,"M_Atef") -> 47 | F4: =COUNTIFS(Test_Cases!M2:M368,"M_Atef",Test_Cases!L2:L368,"Passed") -> 29 | G4: =COUNTIFS(Test_Cases!M2:M368,"M_Atef",Test_Cases!L2:L368,"Failed") -> 8 | H4: =COUNTIFS(Test_Cases!M2:M368,"M_Atef",Test_Cases!L2:L368,"Blocked") -> 0 | I4: =COUNTIFS(Test_Cases!M2:M368,"M_Atef",Test_Cases!L2:L368,"Not_Executed") -> 10
A5: Total User Stories | B5: =COUNTA(User_Stories!A2:A145) -> 144 | D5: Mahmoud Abdalazem | E5: =COUNTIF(Test_Cases!M2:M368,"Mahmoud Abdalazem") -> 0 | F5: =COUNTIFS(Test_Cases!M2:M368,"Mahmoud Abdalazem",Test_Cases!L2:L368,"Passed") -> 0 | G5: =COUNTIFS(Test_Cases!M2:M368,"Mahmoud Abdalazem",Test_Cases!L2:L368,"Failed") -> 0 | H5: =COUNTIFS(Test_Cases!M2:M368,"Mahmoud Abdalazem",Test_Cases!L2:L368,"Blocked") -> 0 | I5: =COUNTIFS(Test_Cases!M2:M368,"Mahmoud Abdalazem",Test_Cases!L2:L368,"Not_Executed") -> 0
A6: Total Test Cases | B6: =COUNTA(Test_Cases!A2:A368) -> 367 | D6: Abdelhamid Anwer | E6: =COUNTIF(Test_Cases!M2:M368,"Abdelhamid Anwer") -> 86 | F6: =COUNTIFS(Test_Cases!M2:M368,"Abdelhamid Anwer",Test_Cases!L2:L368,"Passed") -> 75 | G6: =COUNTIFS(Test_Cases!M2:M368,"Abdelhamid Anwer",Test_Cases!L2:L368,"Failed") -> 10 | H6: =COUNTIFS(Test_Cases!M2:M368,"Abdelhamid Anwer",Test_Cases!L2:L368,"Blocked") -> 0 | I6: =COUNTIFS(Test_Cases!M2:M368,"Abdelhamid Anwer",Test_Cases!L2:L368,"Not_Executed") -> 0
A7: Passed | B7: =COUNTIF(Test_Cases!L2:L368,"Passed") -> 295 | D7: Hamza | E7: =COUNTIF(Test_Cases!M2:M368,"Hamza") -> 47 | F7: =COUNTIFS(Test_Cases!M2:M368,"Hamza",Test_Cases!L2:L368,"Passed") -> 30 | G7: =COUNTIFS(Test_Cases!M2:M368,"Hamza",Test_Cases!L2:L368,"Failed") -> 16 | H7: =COUNTIFS(Test_Cases!M2:M368,"Hamza",Test_Cases!L2:L368,"Blocked") -> 0 | I7: =COUNTIFS(Test_Cases!M2:M368,"Hamza",Test_Cases!L2:L368,"Not_Executed") -> 1
A8: Failed | B8: =COUNTIF(Test_Cases!L2:L368,"Failed") -> 60 | D8: M_Kamel | E8: =COUNTIF(Test_Cases!M2:M368,"M_Kamel") -> 77 | F8: =COUNTIFS(Test_Cases!M2:M368,"M_Kamel",Test_Cases!L2:L368,"Passed") -> 70 | G8: =COUNTIFS(Test_Cases!M2:M368,"M_Kamel",Test_Cases!L2:L368,"Failed") -> 7 | H8: =COUNTIFS(Test_Cases!M2:M368,"M_Kamel",Test_Cases!L2:L368,"Blocked") -> 0 | I8: =COUNTIFS(Test_Cases!M2:M368,"M_Kamel",Test_Cases!L2:L368,"Not_Executed") -> 0
A9: Blocked | B9: =COUNTIF(Test_Cases!L2:L368,"Blocked") -> 0
A10: Not Executed | B10: =COUNTIF(Test_Cases!L2:L368,"Not_Executed") -> 11
A11: Pass Rate | B11: =IFERROR(B5/B4,0) -> 1
A12: Fail Rate | B12: =IFERROR(B6/B4,0) -> 2.5486111
A13: Total Bugs | B13: =COUNTA(Bug_Report!A2:A55) -> 54
A14: Critical Bugs | B14: =COUNTIF(Bug_Report!F2:F55,"Critical") -> 13
A15: High Bugs | B15: =COUNTIF(Bug_Report!F2:F55,"High") -> 18
A16: Medium Bugs | B16: =COUNTIF(Bug_Report!F2:F55,"Medium") -> 12
A17: Low Bugs | B17: =COUNTIF(Bug_Report!F2:F55,"Low") -> 11
A18: Requirements Fully Covered | B18: =COUNTIF(Traceability!J2:J145,"Fully Covered") -> 2
A19: Requirements Partially Covered | B19: =COUNTIF(Traceability!J2:J145,"Partial") -> 5
A20: Requirements Not Covered | B20: =COUNTIF(Traceability!J2:J145,"Not Covered") -> 131
A21: Requirements With Failures | B21: =COUNTIF(Traceability!J2:J145,"Failing") -> 6
A22: Coverage % | B22: =IFERROR((B16+B19)/B2,0) -> 0

Sheet Requirements
A1: Req_ID | B1: Description | C1: Module | D1: Priority | E1: Status | F1: Version
A2: FR-AUTH-01 | B2: The system shall allow new users to register with: phone number (required), username (required), password (required), and either an invitation code or a payment code (required). Email, first name, and last name are optional at registration. | C2: Auth | D2: P1 | E2: Active | F2: v1.0
A3: FR-AUTH-02 | B3: The system shall validate phone number uniqueness and email format at registration, rejecting duplicates with a descriptive error. | C3: Auth | D3: P1 | E3: Active | F3: v1.0
A4: FR-AUTH-03 | B4: Users shall log in using username and password credentials. | C4: Auth | D4: P1 | E4: Active | F4: v1.0
A5: FR-AUTH-04 | B5: Password reset shall be performed by the tenant admin only; the admin generates a new temporary password for the target user. Self-service password reset is not in scope for v1. | C5: Auth | D5: P1 | E5: Active | F5: v1.0
A6: FR-AUTH-05 | B6: Session tokens shall expire after 10 minutes of inactivity; the user shall be prompted to re-authenticate. | C6: Auth | D6: P1 | E6: Active | F6: v1.0
A7: FR-AUTH-06 | B7: Invitation codes are single-use and issued by the tenant admin; each code encodes the recipient's designated role on redemption. | C7: Auth | D7: P1 | E7: Active | F7: v1.0
A8: FR-AUTH-07 | B8: A user may register using a valid payment code in place of an invitation code when the tenant supports the payment-based enrollment model. | C8: Auth | D8: P1 | E8: Active | F8: v1.0
A9: FR-AUTH-08 | B9: The tenant admin can invite and manage users within the limits of the institution's active plan and tier. | C9: Auth | D9: P1 | E9: Active | F9: v1.0
A10: FR-AUTH-09 | B10: Students may join a subscription-based tenant by registering with a payment code that covers the subscription fee; the code amount is credited to the tenant balance. | C10: Auth | D10: P1 | E10: Active | F10: v1.0
A11: FR-AUTH-10 | B11: Students may join a tenant using an invitation code issued by the admin when the tenant operates on an invitation-only enrollment model. | C11: Auth | D11: P1 | E11: Active | F11: v1.0
A12: FR-AUTH-11 | B12: During tenant creation, the institution must specify its student enrollment model: invitation-code only, payment/subscription-based, or both. This setting determines which registration paths are enabled for that tenant. | C12: Tenant Setup | D12: P1 | E12: Active | F12: v1.0
... A145: FR-MNT-03 | B145: The platform shall comply with applicable data protection regulations for the regions in which it operates (e.g., GDPR, Egyptian Personal Data Protection Law). | C145: Compliance | D145: P2 | E145: Active | F145: v1.0

Sheet User_Stories
A1: US_ID | B1: Req_ID | C1: Module | D1: Role | E1: UserStory | F1: AcceptanceCriteria | G1: Priority
A2: US-001 | B2: FR-AUTH-01 | C2: Auth | D2: user | E2: As a user, I want allow new users to register with: phone number (required), username (required), password (required), and either an invitation code or a payment code (required). Email, first name, and last name are optional at registration., so that the auth behaviour meets the requirement. | F2: Given the preconditions defined in FR-AUTH-01, when the action described in the requirement is performed, then the system behaves exactly as specified: The system shall allow new users to register with: phone number (required), username (required), password (required), and either an invitation code or a payment code (required). Email, first name, and last name are optional at registration. | G2: P1
A3: US-002 | B3: FR-AUTH-02 | C3: Auth | D3: user | E3: As a user, I want validate phone number uniqueness and email format at registration, rejecting duplicates with a descriptive error., so that the auth behaviour meets the requirement. | F3: Given the preconditions defined in FR-AUTH-02, when the action described in the requirement is performed, then the system behaves exactly as specified: The system shall validate phone number uniqueness and email format at registration, rejecting duplicates with a descriptive error. | G3: P1
A4: US-003 | B4: FR-AUTH-03 | C4: Auth | D4: user | E4: As a user, I want log in using username and password credentials., so that the auth behaviour meets the requirement. | F4: Given the preconditions defined in FR-AUTH-03, when the action described in the requirement is performed, then the system behaves exactly as specified: Users shall log in using username and password credentials. | G4: P1
A5: US-004 | B5: FR-AUTH-04 | C5: Auth | D5: Head/Admin | E5: As a Head/Admin, I want password reset shall be performed by the tenant admin only; the admin generates a new temporary password for the target user, so that the auth behaviour meets the requirement. | F5: Given the preconditions defined in FR-AUTH-04, when the action described in the requirement is performed, then the system behaves exactly as specified: Password reset shall be performed by the tenant admin only; the admin generates a new temporary password for the target user. Self-service password reset is not in scope for v1. | G5: P1
A6: US-005 | B6: FR-AUTH-05 | C6: Auth | D6: user | E6: As a user, I want session tokens shall expire after 10 minutes of inactivity; the user shall be prompted to re-authenticate., so that the auth behaviour meets the requirement. | F6: Given the preconditions defined in FR-AUTH-05, when the action described in the requirement is performed, then the system behaves exactly as specified: Session tokens shall expire after 10 minutes of inactivity; the user shall be prompted to re-authenticate. | G6: P1
A7: US-006 | B7: FR-AUTH-06 | C7: Auth | D7: Head/Admin | E7: As a Head/Admin, I want invitation codes are single-use and issued by the tenant admin; each code encodes the recipient's designated role on redemption., so that the auth behaviour meets the requirement. | F7: Given the preconditions defined in FR-AUTH-06, when the action described in the requirement is performed, then the system behaves exactly as specified: Invitation codes are single-use and issued by the tenant admin; each code encodes the recipient's designated role on redemption. | G7: P1
A8: US-007 | B8: FR-AUTH-07 | C8: Auth | D8: user | E8: As a user, I want a user may register using a valid payment code in place of an invitation code when the tenant supports the payment-based enrollment model., so that the auth behaviour meets the requirement. | F8: Given the preconditions defined in FR-AUTH-07, when the action described in the requirement is performed, then the system behaves exactly as specified: A user may register using a valid payment code in place of an invitation code when the tenant supports the payment-based enrollment model. | G8: P1
A9: US-008 | B9: FR-AUTH-08 | C9: Auth | D9: Head/Admin | E9: As a Head/Admin, I want can invite and manage users within the limits of the institution's active plan and tier., so that the auth behaviour meets the requirement. | F9: Given the preconditions defined in FR-AUTH-08, when the action described in the requirement is performed, then the system behaves exactly as specified: The tenant admin can invite and manage users within the limits of the institution's active plan and tier. | G9: P1
A10: US-009 | B10: FR-AUTH-09 | C10: Auth | D10: student | E10: As a student, I want join a subscription-based tenant by registering with a payment code that covers the subscription fee; the code amount is credited to the tenant balance., so that the auth behaviour meets the requirement. | F10: Given the preconditions defined in FR-AUTH-09, when the action described in the requirement is performed, then the system behaves exactly as specified: Students may join a subscription-based tenant by registering with a payment code that covers the subscription fee; the code amount is credited to the tenant balance. | G10: P1
A11: US-010 | B11: FR-AUTH-10 | C11: Auth | D11: student | E11: As a student, I want join a tenant using an invitation code issued by the admin when the tenant operates on an invitation-only enrollment model., so that the auth behaviour meets the requirement. | F11: Given the preconditions defined in FR-AUTH-10, when the action described in the requirement is performed, then the system behaves exactly as specified: Students may join a tenant using an invitation code issued by the admin when the tenant operates on an invitation-only enrollment model. | G11: P1
A12: US-011 | B12: FR-AUTH-11 | C12: Tenant Setup | D12: student | E12: As a student, I want the institution must specify its student enrollment model: invitation-code only, payment/subscription-based, or both, so that the tenant setup behaviour meets the requirement. | F12: Given the preconditions defined in FR-AUTH-11, when the action described in the requirement is performed, then the system behaves exactly as specified: During tenant creation, the institution must specify its student enrollment model: invitation-code only, payment/subscription-based, or both. This setting determines which registration paths are enabled for that tenant. | G12: P1
... A145: US-144 | B145: FR-MNT-03 | C145: Compliance | D145: user | E145: As a user, I want the platform shall comply with applicable data protection regulations for the regions in which it operates (e.g., GDPR, Egyptian Personal Data Protection Law)., so that the compliance behaviour meets the requirement. | F145: Given the preconditions defined in FR-MNT-03, when the action described in the requirement is performed, then the system behaves exactly as specified: The platform shall comply with applicable data protection regulations for the regions in which it operates (e.g., GDPR, Egyptian Personal Data Protection Law). | G145: P2

Sheet Test_Cases
A1: TC_ID | B1: Scenario | C1: Req_ID | D1: Title | E1: Description | F1: Preconditions | G1: Test Steps | H1: Test Data | I1: Expected Result | J1: Postconditions | K1: Actual Result | L1: Status | M1: Author | N1: Execution Cycle | O1: Priority
A2: tc_001 | B2: Authontication | C2: FR-AUTH-01 | D2: Verification of Required and Optional Fields Presence on Registration Page | E2: To verify that the registration form displays all the specified fields upon loading, and to ensure that mandatory fields (Phone Number, Username, Password, Invitation/Payment Code) and optional fields (Email, First Name, Last Name) are correctly distinguished visually | F2: 1. The Tenant Portal platform is up and running. 2. The registration URL is publicly accessible without prior authentication | G2: 1. Open the web browser and navigate to the tenant's registration URL. 2. Verify the presence of all required fields and check if they are marked as mandatory 3. Verify the presence of optional fields and ensure they are not marked with mandatory indicators. | H2: N/A | I2: 1. The page loads successfully, displaying the ZAKER AI platform registration interface. 2. All req faild are visiable. | J2: The page remains loaded without submitting data or navigating away, with all input fields ready for user interactions. | K2: 1. The page loads successfully, displaying the ZAKER AI platform registration interface. 2. All req faild are visiable. | L2: Passed | M2: M_Atef | N2: v1.0 | O2: High
A3: tc_002 | B3: Authentication | C3: FR-AUTH-01 | D3: Successful Registration with Admin Invitation Code | E3: To verify that a user can successfully register by providing all mandatory fields and a valid invitation code from the admin | F3: 1. The platform is up and running. 2. A valid invitation code is provided by the admin. | G3: 1. Navigate to the registration page. 2. Enter a valid Phone Number, Username, and Password. 3. Enter the valid Admin Invitation Code. 4. Click the "Register" button. | H3: 1. Valid user details, Admin Code | I3: 1. The system validates the code. 2. The account is created successfully. 3. The user is redirected to the dashboard. | J3: User session is established and redirected to the main page. | K3: 1. The system validates the code. 2. The account is created successfully. 3. The user is redirected to the dashboard. | L3: Passed | M3: M_Atef | N3: v1.0 | O3: High
A4: tc_003 | B4: Authentication | C4: FR-AUTH-01 | D4: Verify Registration Fails When Phone Number Field is Left Blank | E4: To verify that the system blocks account creation and throws a validation error when a user fills out all required details but leaves the Phone Number field empty. | F4: 1. The Tenant Registration page is open and fully loaded. | G4: 1. Fill in all mandatory fields with valid data, but leave the Phone Number field completely blank 2. Click on the "Create Account" button. | H4: 1. Valid user details, Admin Code | I4: 1. Registration is blocked 2. An error massege should be appeare. | J4: No account is created, the user remains on the page, and a specific validation error is displayed. | K4: 1. Registration is blocked 2. An error massege should be appeare. | L4: Passed | M4: M_Atef | N4: v1.0 | O4: High
A5: tc_004 | B5: Authentication | C5: FR-AUTH-01 | D5: Verify Registration Fails When Username Field is Left Blank | E5: To verify that the system blocks account creation and throws a validation error when a user fills out all required details but leaves the Username field empty. | F5: 1. The Tenant Registration page is open and fully loaded. | G5: 1. Fill in all mandatory fields with valid data, but leave the Username field completely blank 2. Click on the "Create Account" button. | H5: 1. Valid user details, Admin Code | I5: 1. Registration is blocked 2. An error massege should be appeare. | J5: No account is created, the user remains on the page, and a specific validation error is displayed. | K5: 1. Registration is blocked 2. An error massege should be appeare. | L5: Passed | M5: M_Atef | N5: v1.0 | O5: High
A6: tc_005 | B6: Authentication | C6: FR-AUTH-01 | D6: Verify Registration Fails When Password Field is Left Blank | E6: To verify that the system blocks account creation and throws a validation error when a user fills out all required details but leaves the Password field empty. | F6: 1. The Tenant Registration page is open and fully loaded. | G6: 1. Fill in all mandatory fields with valid data, but leave the Password field completely blank 2. Click on the "Create Account" button. | H6: 1. Valid user details, Admin Code | I6: 1. Registration is blocked 2. An error massege should be appeare. | J6: No account is created, the user remains on the page, and a specific validation error is displayed. | K6: 1. Registration is blocked 2. An error massege should be appeare. | L6: Passed | M6: M_Atef | N6: v1.0 | O6: High
A7: tc_006 | B7: Authentication | C7: FR-AUTH-01 | D7: Verify Registration Fails When Invitation/Payment Code Field is Left Blank | E7: To verify that the system blocks account creation and throws a validation error when a user fills out all required details but leaves the Code field empty. | F7: 1. The Tenant Registration page is open and fully loaded. | G7: 1. Fill in all mandatory fields with valid data, but leave the Invitation/Payment Code field completely blank 2. Click on the "Create Account" button. | H7: 1. Valid user details, Admin Code | I7: 1. Registration is blocked 2. An error massege should be appeare. | J7: No account is created, the user remains on the page, and a specific validation error is displayed. | K7: 1. Registration is blocked 2. An error massege should be appeare. | L7: Passed | M7: M_Atef | N7: v1.0 | O7: High
A8: tc_007 | B8: Authentication | C8: FR-AUTH-01 | D8: Verify Successful Registration with Empty Optional Fields | E8: To verify that the system successfully creates a new user account when all mandatory fields are provided with valid data, but all optional fields (Email, First Name, Last Name) are left completely blank. | F8: 1. The Tenant Registration page is open and fully loaded. 2. A valid, unused Invitation or Payment Code is available. | G8: 1.Fill in all mandatory fields with valid data, but leave Email, First Name, and Last Name completely blank. 2. Click on the "Create Account" button. | H8: 1. Valid user details, Admin Code | I8: 1. The form submits successfully without any validation errors. 2. The user account is provisioned. 3. The user is redirected to the dashboard. | J8: The account is successfully created in the database, and the user is redirected to the platform dashboard with the appropriate role permissions. | K8: 1. The form submits successfully without any validation errors. 2. The user account is provisioned. 3. The user is redirected to the dashboard. | L8: Passed | M8: M_Atef | N8: v1.0 | O8: High
A9: tc_008 | B9: Authentication | C9: FR-AUTH-01 | D9: Authenticated User Access to Registration Page (Routing Bug) | E9: Verify that an already logged-in user is blocked from accessing the Registration page and is automatically redirected to the dashboard. | F9: 1. A valid user account is successfully logged into the platform. | G9: 1. While logged in, manually type the exact Registration URL in the browser's address bar and hit Enter. 2. Observe the system behavior and the loaded page. | H9: Registration Url: "https://mr-ali-magdy.zakerai.org/register" | I9: 1. Strictly blocks access to the registration form. 2. Automatically redirects the user back to their Home/Tenant Dashboard page smoothly. | J9: The user's active session remains intact, and no unauthenticated routes are rendered | K9: 1. The system allows access to the Registration page and renders the signup form despite the user having an active login session. | L9: Failed | M9: M_Atef | N9: v1.0 | O9: High
A10: tc_009 | B10: Authentication | C10: FR-AUTH-02 | D10: Verify Registration Fails with an Already Registered/Duplicate Phone Number | E10: To verify that the system prevents account creation and displays a descriptive error message when a user tries to register using a phone number that is already associated with an existing account within the same tenant. | F10: 1. A user account already exists in the system database with the phone number: 01277801995 2. The Tenant Registration page is open and fully loaded. | G10: 1.Fill in all mandatory fields with valid data, but use the already registered phone number. 2. Click on the "Create Account" button. | H10: 1. Valid user details, Admin Code 2. Phone : 01277801995 | I10: 1. The registration process is rejected. 2. A clear, descriptive error message is displayed | J10: No new account is created, the database remains unchanged, and the user is blocked on the registration screen with a validation error message. | K10: 1. The registration process is rejected. 2. A clear, descriptive error message is displayed | L10: Passed | M10: M_Atef | N10: v1.0 | O10: High
A11: tc_010 | B11: Authentication | C11: FR-AUTH-02 | D11: Verify Registration Fails with Invalid Email Formats | E11: To verify that the system blocks registration and displays a descriptive error message when the user provides an email address that does not follow the standard format (e.g., missing @, missing domain, or containing invalid characters). | F11: The Tenant Registration page is open and fully loaded. | G11: 1. Fill in all mandatory fields with valid data. 2. In the Email field, enter a format missing the @ symbol. | H11: 1. Valid user details, Admin Code 2. E_mail: mohamed_atefgmail.com | I11: 1. The system blocks submission and displays a descriptive error under the email field | J11: Registration is blocked, no user is created, and an inline validation error appears under the Email field. | K11: 1. The system blocks submission and displays a descriptive error under the email field | L11: Passed | M11: M_Atef | N11: v1.0 | O11: High
A12: tc_011 | B12: Authentication | C12: FR-AUTH-03 | D12: Successful Login (Happy Path) | E12: Verify that a user can successfully log in using a valid registered username and password. | F12: A valid user account exists with username 'mralimagdy_admin' and password '59wnqgF2e3Mo'. The login page is loaded. | G12: 1. Navigate to the login URL. 2. Enter a valid username. 3. Enter a valid password. 4. Click the 'Login' button. | H12: Username: 'mralimagdy_admin' Password: '59wnqgF2e3Mo' | I12: The system authenticates the user and redirects them to the home dashboard smoothly without errors. | J12: User is successfully authenticated, a valid JWT token is issued, and the user is redirected to the tenant dashboard. | K12: The system authenticates the user and redirects them to the home dashboard smoothly without errors. | L12: Passed | M12: M_Atef | N12: v1.0 | O12: High
... A18: tc_017 | B18: Authentication | C18: FR-AUTH-04 | D18: Verify Tenant Admin Can Successfully Generate a Temporary Password for a User | E18: o verify that the Tenant Admin has the functional capability to select a user account, trigger a password reset, and generate a valid temporary password successfully. | F18: 1. The Tenant Admin is logged into the Admin Dashboard 2. A target user account (e.g., student or teacher) exists within the tenant database. | G18: 1. Navigate to the "User Management" section in the Admin Dashboard. 2. Select the target user and click on the "Reset Password" button 3. Confirm the action to generate the temporary password | H18: N/A | I18: 1. The system successfully generates a secure temporary password. 2. A success notification is displayed. 3. The temporary credentials are delivered or shown to the admin. | J18: A temporary password is created, saved in the database, and the user's old password is instantly deactivated | K18: Feature isn'n available till now | L18: Not_Executed | M18: M_Atef | N18: v1.0 | O18: High
A19: tc_018 | B19: Authentication | C19: FR-AUTH-04 | D19: Verify User is Forced to Redirect to 'Change Password' Page on First Login with Temporary Credentials | E19: To verify that when a user logs in using a temporary password generated by the admin, the system automatically redirects them to a mandatory password change screen instead of the home dashboard. | F19: 1. The Tenant Admin has generated a temporary password for the user. 2. The user is on the standard login page | G19: 1. Enter the registered username and the freshly generated temporary password. 2. Click the 'Login' button. | H19: N/A | I19: 1. The system accepts the credentials. 2. Instead of loading the regular dashboard, the UI redirects the user directly to the mandatory /change-password page. 3. A clear prompt is displayed forcing the user to set a new password. | J19: The user session is restricted exclusively to the password update form until a new password is submitted. | L19: Not_Executed | M19: M_Atef | N19: v1.0 | O19: High
A20: tc_019 | B20: Authentication | C20: FR-AUTH-04 | D20: Verify Temporary Password Becomes Invalid After Being Changed | E20: To verify that the temporary password generated by the admin is permanently deactivated once the user uses it to log in and sets a new password. It must not be usable for any subsequent login attempts. | F20: 1. The Tenant Admin has reset the user's password and provided a temporary password. 2. The user has already logged in using that temporary password and successfully 3. updated it to a new custom password.The user is currently logged out. | G20: 1. Navigate to the tenant login page 2.Enter the registered username. 3. Enter the old temporary password provided previously by the admin. 4. Click the 'Login' button. | H20: N/A | I20: 1. The system rejects the login attempt. 2. An error message is displayed (e.g., "Invalid username or password"). | J20: Login is strictly blocked, no session token is generated, and the database rejects the old temporary credentials. | L20: Not_Executed | M20: M_Atef | N20: v1.0 | O20: High
A21: tc_020 | B21: Authentication | C21: FR-AUTH-04 | D21: Verify Successful Login Using the Newly Created Custom Password | E21: To verify that the system successfully authenticates the user when they attempt to log in using their newly updated permanent password after the reset flow. | F21: 1. The user has completed the password reset flow and updated their password to a permanent one. 2. The permanent password is saved in the system database. 3. The login page is loaded. | G21: 1. Navigate to the tenant login page 2.Enter the registered username. 3. Enter the newly created permanent password. 4. Click the 'Login' button. | H21: N/A | I21: 1. The system successfully authenticates the user, generates a JWT token, and redirects them to the home dashboard smoothly. | J21: User is successfully authenticated, a valid JWT token is issued, and the user is redirected to the home dashboard. | L21: Not_Executed | M21: M_Atef | N21: v1.0 | O21: High
A22: tc_021 | B22: Authentication | C22: FR-AUTH-05 | D22: Verify Session Token Expires After 10 Minutes of Total Inactivity | E22: To verify that the system automatically invalidates the session token and prompts the user to re-authenticate if no user activity is detected for a continuous duration of 10 minutes. | F22: 1. The user is successfully logged into the Tenant Dashboard with a valid, active session token | G22: 1. Log into the platform and navigate to any page inside the dashboard. 2. Leave the application completely idle (no mouse movement, no clicks, no keystrokes) for exactly 10 minutes 3. Observe the application interface immediately after the timer expires 4. Try to click on any button or refresh the page to execute a backend activity after expiry | H22: User: mralimagdy_admin pass: 59wnqgF2e3Mo 10 min of waiting | I22: 1. The session token expires server-side. 2. The UI prompts the user to re-authenticate | J22: The session token is completely invalidated, any subsequent API calls return unauthorized, and the user is redirected or prompted to re-log in. | K22: The session expired after 10 minutes of inactivity, and the user was successfully redirected to the login page for re-authentication. | L22: Not_Executed | M22: M_Atef | N22: v1.0 | O22: High
A23: tc_022 | B23: Authentication | C23: FR-AUTH-06 | D23: Verify New User is Assigned 'Teacher' Role Upon Using Teacher Invitation Code | E23: To verify that when a new user registers using an invitation code specifically generated for a Teacher, the system successfully provisions the account with strict Teacher permissions. | F23: 1. The Tenant Admin has generated an invitation code designated for the Teacher role. 2. The registration page is open. | G23: 1. Fill out all required registration fields and enter the Teacher invitation code. 2. Click "Register" and log into the newly created account. | H23: invite code: 68ed27c3-3bed-437d-9965-f48a72516f5b | I23: 1. Registration is successful. 2. The user is assigned the Teacher role. 3. The user can view class rosters but cannot access Admin billing or subscription settings. | J23: The account is created, and the user has access only to Teacher features (e.g., creating exams, viewing assigned classes). | K23: 1. Registration is successful. 2. The user is assigned the Teacher role. 3. The user can view class rosters but cannot access Admin billing or subscription settings. | L23: Passed | M23: M_Atef | N23: v1.0 | O23: High
A24: tc_023 | B24: Authentication | C24: FR-AUTH-06 | D24: Verify New User is Assigned 'Student' Role Upon Using Student Invitation Code | E24: To verify that when a new user registers using an invitation code specifically generated for a Student, the system successfully provisions the account with standard Student limits. | F24: 1. The Tenant Admin has generated an invitation code designated for the Student role. 2. The registration page is open. | G24: 1. Fill out all required registration fields and enter the Student invitation code. 2. Click "Register" and log into the newly created account. | H24: invite code: e270602e-42ea-4623-b0c1-027ba27eb5fe | I24: 1. Registration is successful. 2. The user is assigned the Student role. 3. The user can take assigned exams but cannot create exams or view other students' submissions. | J24: The account is created, and the user has access only to Student features (e.g., taking assigned exams, consuming courses). | K24: 1. Registration is successful. 2. The user is assigned the Student role. 3. The user can take assigned exams but cannot create exams or view other students' submissions. | L24: Passed | M24: M_Atef | N24: v1.0 | O24: High
A25: tc_024 | B25: Authentication | C25: FR-AUTH-06 | D25: Verify 'Admin' Role Assignment via Head Administrator Dashboard Actions | E25: To verify that an Admin account cannot self-register via codes, but is instead officially appointed and assigned tenant-wide permissions internally by the Head role. | F25: 1. The Tenant Admin has generated an invitation code designated for the Admin role. 2. The registration page is open. | G25: 1. Fill out all required registration fields and enter the Admin invitation code. 2. Click "Register" and log into the newly created account. | H25: invite code: b119f744-ecd2-4884-8576-40b0267c08f7 | I25: 1. Registration is successful. 2. The user is assigned the Admin role. 3. The user successfully accesses tenant-wide Admin features (can manage subscriptions, reset passwords, bulk import users) | J25: The target user account is upgraded to Tenant-wide Admin, gaining management access over resources, subscriptions, and billing | K25: 1. Registration is successful. 2. The user is assigned the Admin role. 3. The user successfully accesses tenant-wide Admin features (can manage subscriptions, reset passwords, bulk import users) | L25: Passed | M25: M_Atef | N25: v1.0 | O25: High
A26: tc_025 | B26: Authentication | C26: FR-AUTH-06 | D26: Verify System Blocks Invitation Code Generation for the 'Head' Role | E26: To verify that the system strictly prohibits the Tenant Admin (or any user) from generating an invitation code for the Head role, ensuring that there is always only one Head per organization as per the system design. | F26: 1. A Tenant Admin is logged into the Admin Dashboard. 2. The "Create Invitation Code" panel or endpoint is open. | G26: 1 .Navigate to the "Create Invitation Codes" section in the dashboard. 2. Open the Role Dropdown list to select the designated role for the new code 3. Select the 'Head' role and attempt to click the "Generate Code" button. | H26: 1. Selected Role: Head 2. cc945afc-5c01-46b5-b531-c5ae9b4f7504 | I26: 1. The 'Head' role must NOT be present in the dropdown list (Only Teacher, Student and Admin should be available). 2. [If selectable] The system blocks submission, rejects the request backend-side, and throws an error (e.g., "Cannot generate invitation code for Head role"). | J26: The system blocks the code generation, no database record is created for a Head invitation, and a restriction message is displayed. | K26: 1. The 'Head' role is visible and selectable in the dropdown list. 2. The system successfully generates an invitation code linked to the Head role. | L26: Failed | M26: M_Atef | N26: v1.0 | O26: High
A27: tc_026 | B27: Authentication | C27: FR-AUTH-08 | D27: Verify Registration Succeeds When Active User Count is Below Tier Limit | E27: To verify that the system successfully authenticates and creates a new user account when the current active user count is strictly less than the maximum tier capacity (e.g., 99 active users out of a 100-user limit) | F27: 1. The tenant is active on a plan tier restricted to a maximum of 100 active students/users. 2. The current active user count in the database is less than 100 . 3. The registration page is open. | G27: 1. Fill in all mandatory registration fields with valid data using an unused invitation or payment code. 2. Click on the "Register" / "Create Account" button. | H27: A valid data to regesteration with valid Invitation or payment . | I27: 1. The account is created successfully. 2. Total active user count incremented. | J27: The user account is successfully created and can browse courses and exams | K27: 1. The account is created successfully. 2. Total active user count incremented. | L27: Passed | M27: M_Atef | N27: v1.0 | O27: High
A28: tc_027 | B28: Authentication | C28: FR-AUTH-08 | D28: Verify Registration is Blocked When Active User Count Reaches Tier Limit | E28: To verify that the system strictly blocks any new account provisioning and authentication attempts if the tenant has already met its maximum plan capacity limit (e.g., attempting to register the 101st user when the limit is 100). | F28: 1. The tenant is active on a plan tier restricted to a maximum of 100 active users. 2. The current active user count in the database is exactly 100 (Full Capacity). 3. The registration page is open. | G28: 1. Fill in all mandatory registration fields with valid data using an unused invitation or payment code. 2. Click on the "Register" / "Create Account" button. | H28: A valid data to regesteration with valid Invitation or payment . | I28: 1. The runtime check detects that active users (100) have reached the plan limit (100). 2. Registration is blocked and no record is added to the database. 3. A descriptive error message is displayed (e.g., "Registration blocked: Institution capacity limit reached. Please contact your administrator." | J28: No account is created, the database user count stays at 100/100, and a descriptive plan limit warning/error is shown to the user. | K28: The registration was blocked when the active user limit was reached. No account was created, and an appropriate capacity limit message was displayed. | L28: Not_Executed | M28: M_Atef | N28: v1.0 | O28: High
A29: tc_028 | B29: Authentication | C29: FR-AUTH-10 | D29: Verify Student Can Successfully Register Using a Valid Invitation Code in an Invitation-Only Tenant | E29: To verify that when a specific tenant's setting is configured to work exclusively on an "invitation-only" enrollment model, the system successfully processes the student's registration upon providing a valid, unused invitation code. | F29: 1. A valid, unused student invitation code has been issued by the Tenant Admin 2. The student registration page for this specific tenant is loaded. | G29: 1. Fill out all mandatory registration fields (Phone, Username, Password). 2. In the "Code" field, enter the valid, unused Student Invitation Code. 3. Click on the "Create Account" button. | H29: invite code: e270602e-42ea-4623-b0c1-027ba27eb5fe | I29: 1. The system validates the code against the tenant's model configuration. 2. Registration completes successfully without billing intercepts. 3. The user is redirected to the main Student Dashboard | J29: The student account is successfully provisioned, the user is redirected to the student dashboard, and the code becomes invalid for future use. | K29: 1. The system validates the code against the tenant's model configuration. 2. Registration completes successfully without billing intercepts. 3. The user is redirected to the main Student Dashboard | L29: Passed | M29: M_Atef | N29: v1.0 | O29: High
A30: tc_029 | B30: Authentication | C30: Roles & Permmessions | D30: Verify Student Cannot Access Course Creation Interface or Controls | E30: To verify that when a user with the 'Student' role logs in, the system completely hides or disables all course creation elements (e.g., "Add Course" buttons, creation links) | F30: 1. A valid user account with the Student role exists. 2. The student is successfully logged into the platform. | G30: 1. Navigate to the main Courses tab 2. Visually inspect the top navigation bar, side menus, and page header for any "Add New Course", "Create Course", or "+" buttons. 3. Attempt to manually force access by typing the exact Admin/Teacher course creation URL into the browser's address bar. | H30: Url of create courses :https://mr-ali-magdy.zakerai.org/courses/create | I30: 1. There are no buttons or links related to creating or adding courses visible to the student. 2. The system intercepts the route, blocks access | J30: The student remains restricted to view-only mode, and no course creation interface is rendered | K30: 1. There are no buttons or links related to creating or adding courses visible to the student. 2. The system intercepts the route, blocks access | L30: Passed | M30: M_Atef | N30: v1.0 | O30: High
A31: tc_030 | B31: Authentication | C31: Roles & Permmessions | D31: Verify Tenant Admin Cannot Generate Invitation Codes for the 'Admin' Role | E31: To verify that the system strictly restricts the Tenant Admin from creating or generating an invitation code for the Admin role, enforcing that Admin privileges can only be granted internally by the Head account through role management. | F31: 1. A valid user account with the Admin role exists. 2. The Admin is successfully logged into the platform. | G31: 1. Navigate to the "Invitation Codes" section inside the Admin Dashboard 2. Open the designated Role Dropdown list to choose which role this invitation code will grant upon registration. | H31: N/A | I31: 1. The 'Admin' role must NOT be listed or available as an option in the dropdown (Only Teacher and Student should be selectable). | J31: The system blocks code generation for the Admin role, and the creation action is rejected both on the UI and backend levels. | K31: 1. Admin can create Admin's codes and Head's codes | L31: Failed | M31: M_Atef | N31: v1.0 | O31: High
A32: tc_031 | B32: Courses | C32: FR-CRS-01 | D32: Verify Head Can Successfully Create a New Course | E32: To verify that a user with the 'Head' role can fully create a course with a title, description, cover image, subject, price, and sections. | F32: 1. The Head user is successfully logged into the platform. | G32: 1. Click on the "Create Course" icon on the dashboard. 2. Enter valid course details and click Submit. | H32: A valid title, description, cover image, subject, price, and sections. | I32: 1. The course creation form opens successfully with fields: Title, Description, Cover Image, Subject, Price, and Sections. 2. The backend accepts the request, creates the database record, and a success message appears. | J32: A new Course was appear in Courses page | K32: 1. The form opens successfully. 2. Course is created successfully. | L32: Passed | M32: M_Atef | N32: v1.0 | O32: High
A33: tc_032 | B33: Authentication | C33: FR-CRS-01 | D33: Verify Tenant Admin Can Successfully Create a New Course | E33: To verify that a user with the 'Admin' role can fully create a course with a title, description, cover image, subject, price, and sections. | F33: 1. The Admin user is successfully logged into the platform. | G33: 1. Click on the "Create Course" icon on the dashboard. 2. Enter valid course details and click Submit. | H33: A valid title, description, cover image, subject, price, and sections. | I33: 1. The course creation form opens successfully with fields: Title, Description, Cover Image, Subject, Price, and Sections. 2. The backend accepts the request, creates the database record, and a success message appears. | J33: A new Course was appear in Courses page | K33: 1. The course creation form opens successfully with fields: Title, Description, Cover Image, Subject, Price, and Sections. 2. The backend accepts the request, creates the database record, and a success message appears. | L33: Passed | M33: M_Atef | N33: v1.0 | O33: High
... A158: TC_EXM_110 | B158: Exams | C158: FR-EXM-071 | D158: Verify Exams Dashboard Handles Slow Network Gracefully | E158: Verify that the Exams Dashboard behaves correctly under a slow network connection. | F158: Slow network simulation available. | G158: 1- Log in as Teacher/Admin.2- Simulate Slow 3G network.3- Open the Exams page.4- Perform search, filter and open an exam.5- Observe the application behavior. | H158: Slow 3G Network | I158: The system loads data correctly, displays loading indicators where applicable, and does not produce UI or functional errors. | J158: Dashboard remains stable under poor network conditions. | K158: The system functions as expected and all related configurations were verified successfully without any errors. | L158: Passed | M158: Mahmoud Abdalazem | N158: v1.0 | O158: High
A159: tc-01 | B159: Balance & Payment | C159: BAL-01 | D159: Admin Payment Added to Balance | E159: Verify that redeeming a valid payment code by the Head/Admin correctly increases the tenant balance. | F159: 1. A Head/Admin account exists. 2. The tenant balance is 0 EGP. 3. A valid unused payment code worth 100 EGP exists. | G159: 1. Log in as the Head/Admin. 2. Navigate to the Balance page. 3. Redeem the valid payment code. 4. Refresh the Balance page. | I159: 1. The payment code is redeemed successfully. 2. The tenant balance increases by 100 EGP. 3. The displayed balance is 100 EGP. 4. The redeemed payment code is marked as Redeemed. 5. The balance update is reflected immediately after refresh. | K159: 1. The payment code is redeemed successfully. 2. The tenant balance increases by 100 EGP. 3. The displayed balance is 100 EGP. 4. The redeemed payment code is marked as Redeemed. 5. The balance update is reflected immediately after refresh. | L159: Passed | M159: abdelhamid anwer | N159: v1.0
A160: tc-02 | B160: Balance & Payment | C160: BAL-01 | D160: Multiple Admin Payment Codes | E160: Verify that the tenant balance is updated correctly when the Head/Admin redeems multiple valid payment codes. | F160: 1. A Head/Admin account exists. 2. The tenant balance is 0 EGP. 3. Three valid unused payment codes exist with values of 100 EGP, 150 EGP, and 200 EGP. | G160: 1. Log in as the Head/Admin. 2. Navigate to the Balance page. 3. Redeem the first payment code. 4. Redeem the second payment code. 5. Redeem the third payment code. 6. Refresh the Balance page. | I160: 1. All three payment codes are redeemed successfully. 2. The tenant balance increases by 450 EGP. 3. The displayed balance is 450 EGP. 4. Each payment code is recorded successfully. | K160: 1. All three payment codes are redeemed successfully. 2. The tenant balance increases by 450 EGP. 3. The displayed balance is 450 EGP. 4. Each payment code is recorded successfully. | L160: Passed | M160: abdelhamid anwer | N160: v1.0
A161: tc-03 | B161: Balance & Payment | C161: BAL-01 | D161: Student Payment Added | E161: Verify that the tenant balance increases when a student joins using a valid payment code. | F161: 1. The tenant uses the payment-based enrollment model. 2. A valid unused payment code worth 150 EGP exists. 3. The student is not already registered. | G161: 1. Open the student registration page. 2. Enter valid student information. 3. Enter the valid payment code. 4. Complete the registration. 5. Log in as the Head/Admin. 6. Navigate to the Balance page. | I161: 1. The student account is created successfully. 2. The payment code is redeemed successfully. 3. The tenant balance increases by 150 EGP. 4. The updated balance is displayed correctly. | K161: 1. The student account is created successfully. 2. The payment code is redeemed successfully. 3. The tenant balance increases by 150 EGP. 4. The updated balance is displayed correctly. | L161: Passed | M161: abdelhamid anwer | N161: v1.0
A162: tc-04 | B162: Balance & Payment | C162: BAL-01 | D162: Combined Balance Calculation | E162: Verify that the tenant balance equals the sum of payment codes redeemed by both the Head/Admin and students. | F162: 1. The Head/Admin has redeemed payment codes totaling 300 EGP. 2. Two students have redeemed payment codes totaling 250 EGP. | G162: 1. Log in as the Head/Admin. 2. Navigate to the Balance page. | I162: 1. The displayed balance is 550 EGP. 2. The balance includes both Admin and student payment code values. 3. The balance calculation is accurate. | K162: 1. The displayed balance is 550 EGP. 2. The balance includes both Admin and student payment code values. 3. The balance calculation is accurate. | L162: Passed | M162: abdelhamid anwer | N162: v1.0
A163: tc-05 | B163: Balance & Payment | C163: BAL-01 | D163: Zero Initial Balance | E163: Verify that a newly created tenant has a balance of zero before any payment code is redeemed. | F163: 1. A new tenant has been created. 2. No payment codes have been redeemed. | G163: 1. Log in as the Head/Admin. 2. Navigate to the Balance page. | I163: 1. The displayed balance is 0 EGP. 2. No payment transactions are displayed. | K163: you can't intiate any platform without a balance | L163: Rejected | M163: abdelhamid anwer | N163: v1.0
A164: tc-06 | B164: Balance & Payment | C164: BAL-01 | D164: Failed Redemption Does Not Affect Balance | E164: Verify that an unsuccessful payment code redemption does not change the tenant balance. | F164: 1. The tenant balance is 300 EGP. 2. An invalid payment code is available. | G164: 1. Log in as the Head/Admin. 2. Navigate to the payment redemption page. 3. Enter the invalid payment code. 4. Submit the redemption request. 5. Navigate to the Balance page. | I164: 1. The redemption request is rejected. 2. An appropriate validation message is displayed. 3. The tenant balance remains 300 EGP. 4. No payment transaction is created. | K164: 1. The redemption request is rejected. 2. An appropriate validation message is displayed. 3. The tenant balance remains 300 EGP. 4. No payment transaction is created. | L164: Passed | M164: abdelhamid anwer | N164: v1.0
A165: tc-07 | B165: Balance & Payment | C165: BAL-01 | D165: Other Tenant Payments Excluded | E165: Verify that payment codes redeemed for another tenant are not included in the current tenant's balance. | F165: 1. Tenant A has redeemed payment codes totaling 200 EGP. 2. Tenant B has redeemed payment codes totaling 350 EGP. | G165: 1. Log in as the Head/Admin of Tenant A. 2. Navigate to the Balance page. 3. Record the displayed balance. 4. Log in as the Head/Admin of Tenant B. 5. Navigate to the Balance page. | I165: 1. Tenant A balance is 200 EGP. 2. Tenant B balance is 350 EGP. 3. Each tenant displays only its own balance. | K165: 1. Tenant A balance is 200 EGP. 2. Tenant B balance is 350 EGP. 3. Each tenant displays only its own balance. | L165: Passed | M165: abdelhamid anwer | N165: v1.0
A166: tc-08 | B166: Balance & Payment | C166: BAL-02 | D166: Successful Student Redemption | E166: Verify that a student can successfully redeem a valid payment code and that the payment value is credited to the tenant balance while both payment records are marked as Redeemed. | F166: 1. The tenant uses the payment-based enrollment model. 2. A valid unused payment code exists. 3. The student is not already registered. 4. The payment code belongs to the tenant. | G166: 1. Open the student registration page. 2. Enter valid student information. 3. Enter the valid payment code. 4. Submit the registration. 5. Log in as the Head/Admin. 6. Navigate to the Balance page. 7. Check the payment records. | I166: 1. The student account is created successfully. 2. The payment code is redeemed successfully. 3. The tenant balance increases by the payment code value. 4. The global payment record status is changed to Redeemed. 5. The tenant payment record status is changed to Redeemed. | K166: 1. The student account is created successfully. 2. The payment code is redeemed successfully. 3. The tenant balance increases by the payment code value. 4. The global payment record status is changed to Redeemed. 5. The tenant payment record status is changed to Redeemed. | L166: Passed | M166: abdelhamid anwer | N166: v1.0
A167: tc-10 | B167: Balance & Payment | C167: BAL-02 | D167: Redeemed Payment Code | E167: Verify that a payment code that has already been redeemed cannot be used again. | F167: 1. A payment code already exists with the status Redeemed. | G167: 1. Open the student registration page. 2. Enter valid student information. 3. Enter the redeemed payment code. 4. Submit the registration. | I167: 1. The registration is rejected. 2. An appropriate validation message is displayed. 3. The tenant balance remains unchanged. 4. The payment records remain unchanged. | K167: 1. The registration is rejected. 2. An appropriate validation message is displayed. 3. The tenant balance remains unchanged. 4. The payment records remain unchanged. | L167: Passed | M167: abdelhamid anwer | N167: v1.0
A168: tc-11 | B168: Balance & Payment | C168: BAL-02 | D168: Balance Updated | E168: Verify that the tenant balance is updated by the exact payment code value after a successful redemption. | F168: 1. The tenant balance is 500 EGP. 2. A valid unused payment code worth 150 EGP exists. | G168: 1. Register a student using the valid payment code. 2. Log in as the Head/Admin. 3. Navigate to the Balance page. | I168: 1. The tenant balance becomes 650 EGP. 2. The displayed balance is calculated correctly. | K168: 1. The tenant balance becomes 650 EGP. 2. The displayed balance is calculated correctly. | L168: Passed | M168: abdelhamid anwer | N168: v1.0
A169: tc-12 | B169: Balance & Payment | C169: BAL-03 | D169: Valid Payment Code | E169: Verify that the Head/Admin can successfully redeem a valid unused payment code and the balance is updated. | F169: 1. A Head/Admin account exists. 2. A valid unused payment code exists. 3. The tenant balance is 0 EGP. | G169: 1. Log in as the Head/Admin. 2. Navigate to the Payment Code page. 3. Enter the valid payment code. 4. Submit the payment code. 5. Navigate to the Balance page. | I169: 1. The payment code is accepted. 2. The payment code is marked as Redeemed. 3. The tenant balance increases by the payment code value. 4. A success message is displayed. | K169: 1. The payment code is accepted. 2. The payment code is marked as Redeemed. 3. The tenant balance increases by the payment code value. 4. A success message is displayed. | L169: Passed | M169: abdelhamid anwer | N169: v1.0
...

Sheet Bug_Report
A1: Bug_ID | B1: Module / Feature | C1: Title / Summary | D1: Reported By | E1: Detected In / Test Cycle | F1: Severity | G1: Priority | H1: Environment | I1: TC_ID | J1: Req_ID/US_ID | K1: Description | L1: Steps to Reproduce | M1: Expected Result | N1: Actual Result | O1: Status | P1: Assigned To | Q1: Detected By | R1: Date Logged | S1: Comments / Root Cause
A2: Bug_001 | B2: Authontication | C2: Logged-in user can open '/register' page via URL | D2: M_Atef | E2: v1.0 | F2: Critical | G2: High | H2: Windows 11 / Brave | I2: tc_008 | J2: FR-AUTH-01 | K2: Already logged-in users can manually access the registration page via direct URL instead of being automatically redirected to the dashboard. | L2: 1. While logged in, manually type the exact Registration URL in the browser's address bar and hit Enter. 2. Observe the system behavior and the loaded page. | M2: 1. Strictly blocks access to the registration form. 2. Automatically redirects the user back to their Home/Tenant Dashboard page smoothly. | N2: 1. The system allows access to the Registration page and renders the signup form despite the user having an active login session. | O2: New | P2: M_Kamel | Q2: M_Atef | R2: 2026-07-10
A3: Bug_002 | C3: Logged-in user can open '/login' page via URL | D3: M_Atef | E3: v1.0 | F3: Critical | G3: High | H3: Windows 11 / Brave | I3: tc_015 | J3: FR-AUTH-03 | K3: Already logged-in users can manually access the login page via direct URL instead of being automatically redirected to the dashboard | L3: 1. While logged in, manually type the exact Login URL in the browser's address bar and hit Enter. 2. Observe if the login form is displayed. | M3: 1. The login page is bypassed, and the user is automatically redirected straight to the active dashboard. | N3: 1. The system allows access to the Login page and renders the signin form despite the user having an active login session. | O3: New | P3: M_Kamel | Q3: M_Atef | R3: 2026-07-10
A4: Bug_003 | C4: 'Head' role is visible and allowed during registration code generation | D4: M_Atef | E4: v1.0 | F4: Critical | G4: High | H4: Windows 11 / Brave | I4: tc_025 | J4: FR-AUTH-06 | K4: In the "Generate Join Codes" section, the dropdown menu incorrectly displays the 'Head' role. The system allows generating a registration/enrollment code for a 'Head' account, which violates business logic since these codes are strictly for enrolling students. | L4: 1 .Navigate to the "Create Invitation Codes" section in the dashboard. 2. Open the Role Dropdown list to select the designated role for the new code 3. Select the 'Head' role and attempt to click the "Generate Code" button. | M4: 1. The 'Head' role must NOT be present in the dropdown list (Only Teacher, Student and Admin should be available). 2. [If selectable] The system blocks submission, rejects the request backend-side, and throws an error (e.g., "Cannot generate invitation code for Head role"). | N4: 1. The 'Head' role is visible and selectable in the dropdown list. 2. The system successfully generates an invitation code linked to the Head role. | O4: New | P4: M_Kamel | Q4: M_Atef | R4: 2026-07-10
A5: Bug_004 | C5: Tenant Admin can generate invitation codes for 'Admin' and 'Head' roles | D5: M_Atef | E5: v1.0 | F5: Critical | G5: High | H5: Windows 11 / Brave | I5: tc_030 | J5: Roles & Permmessions | K5: There is a flaw in role management permissions. The Tenant Admin is currently able to create invitation codes for administrative roles ('Admin' and 'Head'). According to business rules, admin privileges must only be granted internally by the Head account through role management, and these high-level roles should not be available for code generation. | L5: 1. Navigate to the "Invitation Codes" section inside the Admin Dashboard 2. Open the designated Role Dropdown list to choose which role this invitation code will grant upon registration. | M5: 1. The 'Admin' role must NOT be listed or available as an option in the dropdown (Only Teacher and Student should be selectable). | N5: 1. Admin can create Admin's codes and Head's codes | O5: New | P5: M_Kamel | Q5: M_Atef | R5: 2026-07-10
A6: Bug_005 | B6: Courses | C6: Teacher role is blocked from creating courses while Admin can create normally | D6: M_Atef | E6: v1.0 | F6: Critical | G6: High | H6: Windows 11 / Brave | I6: tc_033 | J6: FR-CRS-01 | K6: There is a critical permission block for the 'Teacher' role. Users logged in as a Teacher cannot create or add new courses on the platform. However, the creation flow works perfectly fine and normal when logged in as an Admin. | L6: 1. Click on the "Create Course" icon on the dashboard. 2. Enter valid course details and click Submit. | M6: 1. The course creation form opens successfully with fields: Title, Description, Cover Image, Subject, Price, and Sections. 2. The backend accepts the request, creates the database record, and a success message appears. | N6: 1. Course creation is blocked and appear an error message | O6: New | P6: M_Kamel | Q6: M_Atef | R6: 2026-07-10
A7: Bug_006 | C7: Subject dropdown is static and does not allow instructors to add custom subjects | D7: M_Atef | E7: v1.0 | F7: Critical | G7: High | H7: Windows 11 / Brave | I7: tc_034 | J7: FR-CRS-01 | K7: During course creation (Step 1), the "Subject" field is a fixed dropdown menu. Instructors are forced to select only from the pre-defined list and cannot manually type, edit, or add a custom subject of their own choice. | L7: 1. Navigate to the "Subject" field within the course creation form. 2. Attempt to type a new, unique subject name that does not exist in the initial list. | M7: 1. The field should either be a free-text input or a dynamic dropdown that includes an "Add New" or custom creation option. 2. The system accepts the typed input and registers it as the course's subject upon form submission. | N7: 1. The field is a rigid Dropdown menu containing only pre-defined options with no way to type custom text. 2. The dropdown blocks manual keyboard entry and restricts selection only to the old hardcoded list. | O7: New | P7: M_Kamel | Q7: M_Atef | R7: 2026-07-10
